Workbook
Name ChronologieNative_Delivery1: #N/A
Name ChronologieNative_Delivery11: #N/A
Name Début_HCME: PlanFinance!$B$3
Name Délai_Vente: PlanFinance!$C$7
Name Frais_de_Création: PlanFinance!$C$36
Name MarkUp: PlanFinance!$C$6
Name Rglt_à_ESMTP: PlanFinance!$C$13
Name Rglt_à_HCME: PlanFinance!$C$24
Name Segment_Client1: #N/A
Name Segment_Client11: #N/A
Name Segment_LivrAn: #N/A
Name Segment_Site1: #N/A
Name Segment_Site11: #N/A
Name Segment_Status: #N/A
Name Segment_Status11: #N/A
Name Segment_Status111: #N/A
Name Segment_Sub_Dealer: #N/A
Name Segment_Sub_Dealer1: #N/A
Name Segment_Sub_Dealer11: #N/A
Name Segment_Ton.: #N/A
Name TVA: PlanFinance!$C$11
Name VENTE_stock: PlanFinance!$D$7

Sheet Liste Machines
E1: Sous-TOTAL : | F1: =SUBTOTAL(9,LstMachines[Nbre]) -> 63 | G1: machines pr un montant de | I1: =SUBTOTAL(9,LstMachines[Budget]) -> 2765 | J1: k€ | X1: Réception de la machine | Z1: Paiement à HCME | AB1: Livraison des Cdes | AD1: Estim. vente stock | AF1: Rglt si Commande | AH1: Rglt si Vte Stock
B3: Category | C3: Model | D3: Ton. | E3: Model-Spec | F3: Sub-Dealer | G3: Site | H3: Nbre | I3: Budget | J3: Delivery | K3: Status | L3: OriginInfo | M3: Remarque | N3: OrderDate | O3: LivrMois | P3: LivrAn | Q3: OrderNum | R3: OrderPrice | S3: Financement | T3: Confirm | U3: Destination | V3: MachineId | W3: Client | X3: DateLivr | Y3: MoisLivr | Z3: DatePaie | AA3: MoisPaie | AB3: Distrib | AC3: MoisDistrib | AD3: VteESM | AE3: MoisVteESM | AF3: RgltDistrib | AG3: MoisRgltDistrib | AH3: RgltVteESM | AI3: MoisRgltVteESM | AJ3: PayMonth | AK3: PayYear | AL3: - | AM3: Délai souhaité
B4: Mini Pelle | C4: ZX19 | D4: 19 | E4: ZX19U-5 | F4: BTPS | G4: ORTHEZ | H4: 1 | I4: =IF(LstMachines[[#This Row],[Delivery]]<Début_HCME, 0, IFERROR( LstMachines[[#This Row],[Nbre]] * INDEX(TabModelSpecs[],MATCH(LstMachines[[#This Row],[Model-Spec]],TabModelSpecs[ModelSpec],0),MATCH("2018",TabModelSpecs[#Headers],0)), LstMachines[[#This Row],[Nbre]]*ROUND(AVERAGEIF(TabModelSpecs[Machine],LstMachines[[#This Row],[Model]],TabModelSpecs[Price]),0) ) ) -> 0 | J4: 42856 | K4: 1-Forecast | L4: 2017-11 BTPS | O4: =MONTH(LstMachines[[#This Row],[Delivery]]) -> 5 | P4: =FIXED(YEAR(LstMachines[[#This Row],[Delivery]]),0,TRUE) -> 2017 | X4: =LstMachines[[#This Row],[Delivery]] -> 42856 | Y4: =IF(MONTH(LstMachines[[#This Row],[DateLivr]])<10,"0","") & MONTH(LstMachines[[#This Row],[DateLivr]]) &"-"&YEAR(LstMachines[[#This Row],[DateLivr]]) -> 05-2017 | Z4: =LstMachines[[#This Row],[Delivery]]+Rglt_à_HCME -> 42916 | AA4: =IF(MONTH(LstMachines[[#This Row],[DatePaie]])<10,"0","") & MONTH(LstMachines[[#This Row],[DatePaie]])&"-"&YEAR(LstMachines[[#This Row],[DatePaie]]) -> 06-2017 | AB4: =LstMachines[[#This Row],[DateLivr]]+1 -> 42857 | AC4: =IF(MONTH(LstMachines[[#This Row],[Distrib]])<10,"0","") & MONTH(LstMachines[[#This Row],[Distrib]]) & "-" & YEAR(LstMachines[[#This Row],[Distrib]]) -> 05-2017 | AD4: =LstMachines[[#This Row],[DateLivr]]+Délai_Vente -> 42976 | AE4: =IF(MONTH(LstMachines[[#This Row],[VteESM]])<10,"0","") & MONTH(LstMachines[[#This Row],[VteESM]]) & "-" & YEAR(LstMachines[[#This Row],[VteESM]]) -> 08-2017 | AF4: =LstMachines[[#This Row],[DateLivr]]+Rglt_à_ESMTP -> 42916 | AG4: =IF(MONTH(LstMachines[[#This Row],[RgltDistrib]])<10,"0","") & MONTH(LstMachines[[#This Row],[RgltDistrib]]) & "-" & YEAR(LstMachines[[#This Row],[RgltDistrib]]) -> 06-2017 | AH4: =LstMachines[[#This Row],[VteESM]]+Rglt_à_ESMTP -> 43036 | AI4: =IF(MONTH(LstMachines[[#This Row],[RgltVteESM]])<10,"0","") & MONTH(LstMachines[[#This Row],[RgltVteESM]]) & "-" & YEAR(LstMachines[[#This Row],[RgltVteESM]]) -> 10-2017 | AJ4: =MONTH(LstMachines[[#This Row],[DatePaie]]) -> 6 | AK4: =FIXED(YEAR(LstMachines[[#This Row],[DatePaie]]),0,TRUE) -> 2017
B5: Mini Pelle | C5: ZX55 | D5: 55 | E5: ZX55U-5-CLRNH | F5: BTPS | G5: ORTHEZ | H5: 1 | I5: =IF(LstMachines[[#This Row],[Delivery]]<Début_HCME, 0, IFERROR( LstMachines[[#This Row],[Nbre]] * INDEX(TabModelSpecs[],MATCH(LstMachines[[#This Row],[Model-Spec]],TabModelSpecs[ModelSpec],0),MATCH("2018",TabModelSpecs[#Headers],0)), LstMachines[[#This Row],[Nbre]]*ROUND(AVERAGEIF(TabModelSpecs[Machine],LstMachines[[#This Row],[Model]],TabModelSpecs[Price]),0) ) ) -> 0 | J5: 42870 | K5: 1-Forecast | L5: 2017-11 BTPS | O5: =MONTH(LstMachines[[#This Row],[Delivery]]) -> 5 | P5: =FIXED(YEAR(LstMachines[[#This Row],[Delivery]]),0,TRUE) -> 2017 | X5: =LstMachines[[#This Row],[Delivery]] -> 42870 | Y5: =IF(MONTH(LstMachines[[#This Row],[DateLivr]])<10,"0","") & MONTH(LstMachines[[#This Row],[DateLivr]]) &"-"&YEAR(LstMachines[[#This Row],[DateLivr]]) -> 05-2017 | Z5: =LstMachines[[#This Row],[Delivery]]+Rglt_à_HCME -> 42930 | AA5: =IF(MONTH(LstMachines[[#This Row],[DatePaie]])<10,"0","") & MONTH(LstMachines[[#This Row],[DatePaie]])&"-"&YEAR(LstMachines[[#This Row],[DatePaie]]) -> 07-2017 | AB5: =LstMachines[[#This Row],[DateLivr]]+1 -> 42871 | AC5: =IF(MONTH(LstMachines[[#This Row],[Distrib]])<10,"0","") & MONTH(LstMachines[[#This Row],[Distrib]]) & "-" & YEAR(LstMachines[[#This Row],[Distrib]]) -> 05-2017 | AD5: =LstMachines[[#This Row],[DateLivr]]+Délai_Vente -> 42990 | AE5: =IF(MONTH(LstMachines[[#This Row],[VteESM]])<10,"0","") & MONTH(LstMachines[[#This Row],[VteESM]]) & "-" & YEAR(LstMachines[[#This Row],[VteESM]]) -> 09-2017 | AF5: =LstMachines[[#This Row],[DateLivr]]+Rglt_à_ESMTP -> 42930 | AG5: =IF(MONTH(LstMachines[[#This Row],[RgltDistrib]])<10,"0","") & MONTH(LstMachines[[#This Row],[RgltDistrib]]) & "-" & YEAR(LstMachines[[#This Row],[RgltDistrib]]) -> 07-2017 | AH5: =LstMachines[[#This Row],[VteESM]]+Rglt_à_ESMTP -> 43050 | AI5: =IF(MONTH(LstMachines[[#This Row],[RgltVteESM]])<10,"0","") & MONTH(LstMachines[[#This Row],[RgltVteESM]]) & "-" & YEAR(LstMachines[[#This Row],[RgltVteESM]]) -> 11-2017 | AJ5: =MONTH(LstMachines[[#This Row],[DatePaie]]) -> 7 | AK5: =FIXED(YEAR(LstMachines[[#This Row],[DatePaie]]),0,TRUE) -> 2017
B6: Pelle/Chenilles | C6: ZX85 | D6: 85 | E6: ZX85USB-5A-Mono | F6: BTPS | G6: ORTHEZ | H6: 1 | I6: =IF(LstMachines[[#This Row],[Delivery]]<Début_HCME, 0, IFERROR( LstMachines[[#This Row],[Nbre]] * INDEX(TabModelSpecs[],MATCH(LstMachines[[#This Row],[Model-Spec]],TabModelSpecs[ModelSpec],0),MATCH("2018",TabModelSpecs[#Headers],0)), LstMachines[[#This Row],[Nbre]]*ROUND(AVERAGEIF(TabModelSpecs[Machine],LstMachines[[#This Row],[Model]],TabModelSpecs[Price]),0) ) ) -> 0 | J6: 42870 | K6: 1-Forecast | L6: 2017-11 BTPS | O6: =MONTH(LstMachines[[#This Row],[Delivery]]) -> 5 | P6: =FIXED(YEAR(LstMachines[[#This Row],[Delivery]]),0,TRUE) -> 2017 | X6: =LstMachines[[#This Row],[Delivery]] -> 42870 | Y6: =IF(MONTH(LstMachines[[#This Row],[DateLivr]])<10,"0","") & MONTH(LstMachines[[#This Row],[DateLivr]]) &"-"&YEAR(LstMachines[[#This Row],[DateLivr]]) -> 05-2017 | Z6: =LstMachines[[#This Row],[Delivery]]+Rglt_à_HCME -> 42930 | AA6: =IF(MONTH(LstMachines[[#This Row],[DatePaie]])<10,"0","") & MONTH(LstMachines[[#This Row],[DatePaie]])&"-"&YEAR(LstMachines[[#This Row],[DatePaie]]) -> 07-2017 | AB6: =LstMachines[[#This Row],[DateLivr]]+1 -> 42871 | AC6: =IF(MONTH(LstMachines[[#This Row],[Distrib]])<10,"0","") & MONTH(LstMachines[[#This Row],[Distrib]]) & "-" & YEAR(LstMachines[[#This Row],[Distrib]]) -> 05-2017 | AD6: =LstMachines[[#This Row],[DateLivr]]+Délai_Vente -> 42990 | AE6: =IF(MONTH(LstMachines[[#This Row],[VteESM]])<10,"0","") & MONTH(LstMachines[[#This Row],[VteESM]]) & "-" & YEAR(LstMachines[[#This Row],[VteESM]]) -> 09-2017 | AF6: =LstMachines[[#This Row],[DateLivr]]+Rglt_à_ESMTP -> 42930 | AG6: =IF(MONTH(LstMachines[[#This Row],[RgltDistrib]])<10,"0","") & MONTH(LstMachines[[#This Row],[RgltDistrib]]) & "-" & YEAR(LstMachines[[#This Row],[RgltDistrib]]) -> 07-2017 | AH6: =LstMachines[[#This Row],[VteESM]]+Rglt_à_ESMTP -> 43050 | AI6: =IF(MONTH(LstMachines[[#This Row],[RgltVteESM]])<10,"0","") & MONTH(LstMachines[[#This Row],[RgltVteESM]]) & "-" & YEAR(LstMachines[[#This Row],[RgltVteESM]]) -> 11-2017 | AJ6: =MONTH(LstMachines[[#This Row],[DatePaie]]) -> 7 | AK6: =FIXED(YEAR(LstMachines[[#This Row],[DatePaie]]),0,TRUE) -> 2017
B7: Pelle/Chenilles | C7: ZX190 | D7: 190 | E7: ZX190LC-6-MN | F7: SETP | G7: RABASTENS | H7: 1 | I7: =IF(LstMachines[[#This Row],[Delivery]]<Début_HCME, 0, IFERROR( LstMachines[[#This Row],[Nbre]] * INDEX(TabModelSpecs[],MATCH(LstMachines[[#This Row],[Model-Spec]],TabModelSpecs[ModelSpec],0),MATCH("2018",TabModelSpecs[#Headers],0)), LstMachines[[#This Row],[Nbre]]*ROUND(AVERAGEIF(TabModelSpecs[Machine],LstMachines[[#This Row],[Model]],TabModelSpecs[Price]),0) ) ) -> 0 | J7: 42901 | K7: 5-Livrée | L7: 2017-05 Forecast | O7: =MONTH(LstMachines[[#This Row],[Delivery]]) -> 6 | P7: =FIXED(YEAR(LstMachines[[#This Row],[Delivery]]),0,TRUE) -> 2017 | U7: VENTE | W7: _Location | X7: =LstMachines[[#This Row],[Delivery]] -> 42901 | Y7: =IF(MONTH(LstMachines[[#This Row],[DateLivr]])<10,"0","") & MONTH(LstMachines[[#This Row],[DateLivr]]) &"-"&YEAR(LstMachines[[#This Row],[DateLivr]]) -> 06-2017 | Z7: =LstMachines[[#This Row],[Delivery]]+Rglt_à_HCME -> 42961 | AA7: =IF(MONTH(LstMachines[[#This Row],[DatePaie]])<10,"0","") & MONTH(LstMachines[[#This Row],[DatePaie]])&"-"&YEAR(LstMachines[[#This Row],[DatePaie]]) -> 08-2017 | AB7: =LstMachines[[#This Row],[DateLivr]]+1 -> 42902 | AC7: =IF(MONTH(LstMachines[[#This Row],[Distrib]])<10,"0","") & MONTH(LstMachines[[#This Row],[Distrib]]) & "-" & YEAR(LstMachines[[#This Row],[Distrib]]) -> 06-2017 | AD7: =LstMachines[[#This Row],[DateLivr]]+Délai_Vente -> 43021 | AE7: =IF(MONTH(LstMachines[[#This Row],[VteESM]])<10,"0","") & MONTH(LstMachines[[#This Row],[VteESM]]) & "-" & YEAR(LstMachines[[#This Row],[VteESM]]) -> 10-2017 | AF7: =LstMachines[[#This Row],[DateLivr]]+Rglt_à_ESMTP -> 42961 | AG7: =IF(MONTH(LstMachines[[#This Row],[RgltDistrib]])<10,"0","") & MONTH(LstMachines[[#This Row],[RgltDistrib]]) & "-" & YEAR(LstMachines[[#This Row],[RgltDistrib]]) -> 08-2017 | AH7: =LstMachines[[#This Row],[VteESM]]+Rglt_à_ESMTP -> 43081 | AI7: =IF(MONTH(LstMachines[[#This Row],[RgltVteESM]])<10,"0","") & MONTH(LstMachines[[#This Row],[RgltVteESM]]) & "-" & YEAR(LstMachines[[#This Row],[RgltVteESM]]) -> 12-2017 | AJ7: =MONTH(LstMachines[[#This Row],[DatePaie]]) -> 8 | AK7: =FIXED(YEAR(LstMachines[[#This Row],[DatePaie]]),0,TRUE) -> 2017
B8: Pelle/Chenilles | C8: ZX300 | D8: 300 | E8: ZX300LCN-6-MN | F8: SETP | H8: 1 | I8: =IF(LstMachines[[#This Row],[Delivery]]<Début_HCME, 0, IFERROR( LstMachines[[#This Row],[Nbre]] * INDEX(TabModelSpecs[],MATCH(LstMachines[[#This Row],[Model-Spec]],TabModelSpecs[ModelSpec],0),MATCH("2018",TabModelSpecs[#Headers],0)), LstMachines[[#This Row],[Nbre]]*ROUND(AVERAGEIF(TabModelSpecs[Machine],LstMachines[[#This Row],[Model]],TabModelSpecs[Price]),0) ) ) -> 0 | J8: 42901 | K8: 5-Livrée | L8: 2017-10 ADV | N8: 42795 | O8: =MONTH(LstMachines[[#This Row],[Delivery]]) -> 6 | P8: =FIXED(YEAR(LstMachines[[#This Row],[Delivery]]),0,TRUE) -> 2017 | X8: =LstMachines[[#This Row],[Delivery]] -> 42901 | Y8: =IF(MONTH(LstMachines[[#This Row],[DateLivr]])<10,"0","") & MONTH(LstMachines[[#This Row],[DateLivr]]) &"-"&YEAR(LstMachines[[#This Row],[DateLivr]]) -> 06-2017 | Z8: =LstMachines[[#This Row],[Delivery]]+Rglt_à_HCME -> 42961 | AA8: =IF(MONTH(LstMachines[[#This Row],[DatePaie]])<10,"0","") & MONTH(LstMachines[[#This Row],[DatePaie]])&"-"&YEAR(LstMachines[[#This Row],[DatePaie]]) -> 08-2017 | AB8: =LstMachines[[#This Row],[DateLivr]]+1 -> 42902 | AC8: =IF(MONTH(LstMachines[[#This Row],[Distrib]])<10,"0","") & MONTH(LstMachines[[#This Row],[Distrib]]) & "-" & YEAR(LstMachines[[#This Row],[Distrib]]) -> 06-2017 | AD8: =LstMachines[[#This Row],[DateLivr]]+Délai_Vente -> 43021 | AE8: =IF(MONTH(LstMachines[[#This Row],[VteESM]])<10,"0","") & MONTH(LstMachines[[#This Row],[VteESM]]) & "-" & YEAR(LstMachines[[#This Row],[VteESM]]) -> 10-2017 | AF8: =LstMachines[[#This Row],[DateLivr]]+Rglt_à_ESMTP -> 42961 | AG8: =IF(MONTH(LstMachines[[#This Row],[RgltDistrib]])<10,"0","") & MONTH(LstMachines[[#This Row],[RgltDistrib]]) & "-" & YEAR(LstMachines[[#This Row],[RgltDistrib]]) -> 08-2017 | AH8: =LstMachines[[#This Row],[VteESM]]+Rglt_à_ESMTP -> 43081 | AI8: =IF(MONTH(LstMachines[[#This Row],[RgltVteESM]])<10,"0","") & MONTH(LstMachines[[#This Row],[RgltVteESM]]) & "-" & YEAR(LstMachines[[#This Row],[RgltVteESM]]) -> 12-2017 | AJ8: =MONTH(LstMachines[[#This Row],[DatePaie]]) -> 8 | AK8: =FIXED(YEAR(LstMachines[[#This Row],[DatePaie]]),0,TRUE) -> 2017
B9: Pelle/Chenilles | C9: ZX85 | D9: 85 | E9: ZX85USB-5A-Mono | F9: SETP | G9: RABASTENS | H9: 1 | I9: =IF(LstMachines[[#This Row],[Delivery]]<Début_HCME, 0, IFERROR( LstMachines[[#This Row],[Nbre]] * INDEX(TabModelSpecs[],MATCH(LstMachines[[#This Row],[Model-Spec]],TabModelSpecs[ModelSpec],0),MATCH("2018",TabModelSpecs[#Headers],0)), LstMachines[[#This Row],[Nbre]]*ROUND(AVERAGEIF(TabModelSpecs[Machine],LstMachines[[#This Row],[Model]],TabModelSpecs[Price]),0) ) ) -> 0 | J9: 42931 | K9: 5-Livrée | L9: 2017-10 ADV | N9: 42853 | O9: =MONTH(LstMachines[[#This Row],[Delivery]]) -> 7 | P9: =FIXED(YEAR(LstMachines[[#This Row],[Delivery]]),0,TRUE) -> 2017 | Q9: 17040041 | R9: 56981 | T9: 1-05114-1 | U9: VENTE | V9: 4111 | W9: RECTANGLE BLEU | X9: =LstMachines[[#This Row],[Delivery]] -> 42931 | Y9: =IF(MONTH(LstMachines[[#This Row],[DateLivr]])<10,"0","") & MONTH(LstMachines[[#This Row],[DateLivr]]) &"-"&YEAR(LstMachines[[#This Row],[DateLivr]]) -> 07-2017 | Z9: =LstMachines[[#This Row],[Delivery]]+Rglt_à_HCME -> 42991 | AA9: =IF(MONTH(LstMachines[[#This Row],[DatePaie]])<10,"0","") & MONTH(LstMachines[[#This Row],[DatePaie]])&"-"&YEAR(LstMachines[[#This Row],[DatePaie]]) -> 09-2017 | AB9: =LstMachines[[#This Row],[DateLivr]]+1 -> 42932 | AC9: =IF(MONTH(LstMachines[[#This Row],[Distrib]])<10,"0","") & MONTH(LstMachines[[#This Row],[Distrib]]) & "-" & YEAR(LstMachines[[#This Row],[Distrib]]) -> 07-2017 | AD9: =LstMachines[[#This Row],[DateLivr]]+Délai_Vente -> 43051 | AE9: =IF(MONTH(LstMachines[[#This Row],[VteESM]])<10,"0","") & MONTH(LstMachines[[#This Row],[VteESM]]) & "-" & YEAR(LstMachines[[#This Row],[VteESM]]) -> 11-2017 | AF9: =LstMachines[[#This Row],[DateLivr]]+Rglt_à_ESMTP -> 42991 | AG9: =IF(MONTH(LstMachines[[#This Row],[RgltDistrib]])<10,"0","") & MONTH(LstMachines[[#This Row],[RgltDistrib]]) & "-" & YEAR(LstMachines[[#This Row],[RgltDistrib]]) -> 09-2017 | AH9: =LstMachines[[#This Row],[VteESM]]+Rglt_à_ESMTP -> 43111 | AI9: =IF(MONTH(LstMachines[[#This Row],[RgltVteESM]])<10,"0","") & MONTH(LstMachines[[#This Row],[RgltVteESM]]) & "-" & YEAR(LstMachines[[#This Row],[RgltVteESM]]) -> 01-2018 | AJ9: =MONTH(LstMachines[[#This Row],[DatePaie]]) -> 9 | AK9: =FIXED(YEAR(LstMachines[[#This Row],[DatePaie]]),0,TRUE) -> 2017
B10: Chargeuse | C10: ZW180 | D10: 180 | E10: ZW180-6-TPD | F10: SETP | G10: RABASTENS | H10: 1 | I10: =IF(LstMachines[[#This Row],[Delivery]]<Début_HCME, 0, IFERROR( LstMachines[[#This Row],[Nbre]] * INDEX(TabModelSpecs[],MATCH(LstMachines[[#This Row],[Model-Spec]],TabModelSpecs[ModelSpec],0),MATCH("2018",TabModelSpecs[#Headers],0)), LstMachines[[#This Row],[Nbre]]*ROUND(AVERAGEIF(TabModelSpecs[Machine],LstMachines[[#This Row],[Model]],TabModelSpecs[Price]),0) ) ) -> 0 | J10: 42962 | K10: 5-Livrée | L10: 2017-12-06 ADV | N10: 42853 | O10: =MONTH(LstMachines[[#This Row],[Delivery]]) -> 8 | P10: =FIXED(YEAR(LstMachines[[#This Row],[Delivery]]),0,TRUE) -> 2017 | Q10: 17040092 | R10: 101896 | T10: 1-04917-1 798 | U10: VENTE | V10: 4118 | W10: CARCELLER | X10: =LstMachines[[#This Row],[Delivery]] -> 42962 | Y10: =IF(MONTH(LstMachines[[#This Row],[DateLivr]])<10,"0","") & MONTH(LstMachines[[#This Row],[DateLivr]]) &"-"&YEAR(LstMachines[[#This Row],[DateLivr]]) -> 08-2017 | Z10: =LstMachines[[#This Row],[Delivery]]+Rglt_à_HCME -> 43022 | AA10: =IF(MONTH(LstMachines[[#This Row],[DatePaie]])<10,"0","") & MONTH(LstMachines[[#This Row],[DatePaie]])&"-"&YEAR(LstMachines[[#This Row],[DatePaie]]) -> 10-2017 | AB10: =LstMachines[[#This Row],[DateLivr]]+1 -> 42963 | AC10: =IF(MONTH(LstMachines[[#This Row],[Distrib]])<10,"0","") & MONTH(LstMachines[[#This Row],[Distrib]]) & "-" & YEAR(LstMachines[[#This Row],[Distrib]]) -> 08-2017 | AD10: =LstMachines[[#This Row],[DateLivr]]+Délai_Vente -> 43082 | AE10: =IF(MONTH(LstMachines[[#This Row],[VteESM]])<10,"0","") & MONTH(LstMachines[[#This Row],[VteESM]]) & "-" & YEAR(LstMachines[[#This Row],[VteESM]]) -> 12-2017 | AF10: =LstMachines[[#This Row],[DateLivr]]+Rglt_à_ESMTP -> 43022 | AG10: =IF(MONTH(LstMachines[[#This Row],[RgltDistrib]])<10,"0","") & MONTH(LstMachines[[#This Row],[RgltDistrib]]) & "-" & YEAR(LstMachines[[#This Row],[RgltDistrib]]) -> 10-2017 | AH10: =LstMachines[[#This Row],[VteESM]]+Rglt_à_ESMTP -> 43142 | AI10: =IF(MONTH(LstMachines[[#This Row],[RgltVteESM]])<10,"0","") & MONTH(LstMachines[[#This Row],[RgltVteESM]]) & "-" & YEAR(LstMachines[[#This Row],[RgltVteESM]]) -> 02-2018 | AJ10: =MONTH(LstMachines[[#This Row],[DatePaie]]) -> 10 | AK10: =FIXED(YEAR(LstMachines[[#This Row],[DatePaie]]),0,TRUE) -> 2017
B11: Pelle/Chenilles | C11: ZX135 | D11: 135 | E11: ZX135US-6-2P-BL | F11: SETP | G11: RABASTENS | H11: 1 | I11: =IF(LstMachines[[#This Row],[Delivery]]<Début_HCME, 0, IFERROR( LstMachines[[#This Row],[Nbre]] * INDEX(TabModelSpecs[],MATCH(LstMachines[[#This Row],[Model-Spec]],TabModelSpecs[ModelSpec],0),MATCH("2018",TabModelSpecs[#Headers],0)), LstMachines[[#This Row],[Nbre]]*ROUND(AVERAGEIF(TabModelSpecs[Machine],LstMachines[[#This Row],[Model]],TabModelSpecs[Price]),0) ) ) -> 0 | J11: 42962 | K11: 5-Livrée | L11: 2017-10 ADV | N11: 42794 | O11: =MONTH(LstMachines[[#This Row],[Delivery]]) -> 8 | P11: =FIXED(YEAR(LstMachines[[#This Row],[Delivery]]),0,TRUE) -> 2017 | Q11: 17020004 | R11: 105100 | T11: 1-04628-1 821 | U11: VENTE | V11: 4188 | W11: NEROCAN | X11: =LstMachines[[#This Row],[Delivery]] -> 42962 | Y11: =IF(MONTH(LstMachines[[#This Row],[DateLivr]])<10,"0","") & MONTH(LstMachines[[#This Row],[DateLivr]]) &"-"&YEAR(LstMachines[[#This Row],[DateLivr]]) -> 08-2017 | Z11: =LstMachines[[#This Row],[Delivery]]+Rglt_à_HCME -> 43022 | AA11: =IF(MONTH(LstMachines[[#This Row],[DatePaie]])<10,"0","") & MONTH(LstMachines[[#This Row],[DatePaie]])&"-"&YEAR(LstMachines[[#This Row],[DatePaie]]) -> 10-2017 | AB11: =LstMachines[[#This Row],[DateLivr]]+1 -> 42963 | AC11: =IF(MONTH(LstMachines[[#This Row],[Distrib]])<10,"0","") & MONTH(LstMachines[[#This Row],[Distrib]]) & "-" & YEAR(LstMachines[[#This Row],[Distrib]]) -> 08-2017 | AD11: =LstMachines[[#This Row],[DateLivr]]+Délai_Vente -> 43082 | AE11: =IF(MONTH(LstMachines[[#This Row],[VteESM]])<10,"0","") & MONTH(LstMachines[[#This Row],[VteESM]]) & "-" & YEAR(LstMachines[[#This Row],[VteESM]]) -> 12-2017 | AF11: =LstMachines[[#This Row],[DateLivr]]+Rglt_à_ESMTP -> 43022 | AG11: =IF(MONTH(LstMachines[[#This Row],[RgltDistrib]])<10,"0","") & MONTH(LstMachines[[#This Row],[RgltDistrib]]) & "-" & YEAR(LstMachines[[#This Row],[RgltDistrib]]) -> 10-2017 | AH11: =LstMachines[[#This Row],[VteESM]]+Rglt_à_ESMTP -> 43142 | AI11: =IF(MONTH(LstMachines[[#This Row],[RgltVteESM]])<10,"0","") & MONTH(LstMachines[[#This Row],[RgltVteESM]]) & "-" & YEAR(LstMachines[[#This Row],[RgltVteESM]]) -> 02-2018 | AJ11: =MONTH(LstMachines[[#This Row],[DatePaie]]) -> 10 | AK11: =FIXED(YEAR(LstMachines[[#This Row],[DatePaie]]),0,TRUE) -> 2017
B12: Pelle/Chenilles | C12: ZX85 | D12: 85 | E12: ZX85USB-5A-Mono | F12: SETP | G12: RABASTENS | H12: 1 | I12: =IF(LstMachines[[#This Row],[Delivery]]<Début_HCME, 0, IFERROR( LstMachines[[#This Row],[Nbre]] * INDEX(TabModelSpecs[],MATCH(LstMachines[[#This Row],[Model-Spec]],TabModelSpecs[ModelSpec],0),MATCH("2018",TabModelSpecs[#Headers],0)), LstMachines[[#This Row],[Nbre]]*ROUND(AVERAGEIF(TabModelSpecs[Machine],LstMachines[[#This Row],[Model]],TabModelSpecs[Price]),0) ) ) -> 0 | J12: 42962 | K12: 5-Livrée | L12: 2017-10 ADV | N12: 42853 | O12: =MONTH(LstMachines[[#This Row],[Delivery]]) -> 8 | P12: =FIXED(YEAR(LstMachines[[#This Row],[Delivery]]),0,TRUE) -> 2017 | Q12: 17040042 | R12: 56981 | T12: 1-05115-1 820 | U12: VENTE | V12: 4112 | W12: PRUNET | X12: =LstMachines[[#This Row],[Delivery]] -> 42962 | Y12: =IF(MONTH(LstMachines[[#This Row],[DateLivr]])<10,"0","") & MONTH(LstMachines[[#This Row],[DateLivr]]) &"-"&YEAR(LstMachines[[#This Row],[DateLivr]]) -> 08-2017 | Z12: =LstMachines[[#This Row],[Delivery]]+Rglt_à_HCME -> 43022 | AA12: =IF(MONTH(LstMachines[[#This Row],[DatePaie]])<10,"0","") & MONTH(LstMachines[[#This Row],[DatePaie]])&"-"&YEAR(LstMachines[[#This Row],[DatePaie]]) -> 10-2017 | AB12: =LstMachines[[#This Row],[DateLivr]]+1 -> 42963 | AC12: =IF(MONTH(LstMachines[[#This Row],[Distrib]])<10,"0","") & MONTH(LstMachines[[#This Row],[Distrib]]) & "-" & YEAR(LstMachines[[#This Row],[Distrib]]) -> 08-2017 | AD12: =LstMachines[[#This Row],[DateLivr]]+Délai_Vente -> 43082 | AE12: =IF(MONTH(LstMachines[[#This Row],[VteESM]])<10,"0","") & MONTH(LstMachines[[#This Row],[VteESM]]) & "-" & YEAR(LstMachines[[#This Row],[VteESM]]) -> 12-2017 | AF12: =LstMachines[[#This Row],[DateLivr]]+Rglt_à_ESMTP -> 43022 | AG12: =IF(MONTH(LstMachines[[#This Row],[RgltDistrib]])<10,"0","") & MONTH(LstMachines[[#This Row],[RgltDistrib]]) & "-" & YEAR(LstMachines[[#This Row],[RgltDistrib]]) -> 10-2017 | AH12: =LstMachines[[#This Row],[VteESM]]+Rglt_à_ESMTP -> 43142 | AI12: =IF(MONTH(LstMachines[[#This Row],[RgltVteESM]])<10,"0","") & MONTH(LstMachines[[#This Row],[RgltVteESM]]) & "-" & YEAR(LstMachines[[#This Row],[RgltVteESM]]) -> 02-2018 | AJ12: =MONTH(LstMachines[[#This Row],[DatePaie]]) -> 10 | AK12: =FIXED(YEAR(LstMachines[[#This Row],[DatePaie]]),0,TRUE) -> 2017
B13: Pelle/Pneus | C13: ZX145 | D13: 145 | E13: ZX145W-6-2P | F13: SETP | G13: RABASTENS | H13: 1 | I13: =IF(LstMachines[[#This Row],[Delivery]]<Début_HCME, 0, IFERROR( LstMachines[[#This Row],[Nbre]] * INDEX(TabModelSpecs[],MATCH(LstMachines[[#This Row],[Model-Spec]],TabModelSpecs[ModelSpec],0),MATCH("2018",TabModelSpecs[#Headers],0)), LstMachines[[#This Row],[Nbre]]*ROUND(AVERAGEIF(TabModelSpecs[Machine],LstMachines[[#This Row],[Model]],TabModelSpecs[Price]),0) ) ) -> 0 | J13: 42962 | K13: ** Lost ** | L13: 2017-10 ADV | M13: ** Lost ** | N13: 42887 | O13: =MONTH(LstMachines[[#This Row],[Delivery]]) -> 8 | P13: =FIXED(YEAR(LstMachines[[#This Row],[Delivery]]),0,TRUE) -> 2017 | X13: =LstMachines[[#This Row],[Delivery]] -> 42962 | Y13: =IF(MONTH(LstMachines[[#This Row],[DateLivr]])<10,"0","") & MONTH(LstMachines[[#This Row],[DateLivr]]) &"-"&YEAR(LstMachines[[#This Row],[DateLivr]]) -> 08-2017 | Z13: =LstMachines[[#This Row],[Delivery]]+Rglt_à_HCME -> 43022 | AA13: =IF(MONTH(LstMachines[[#This Row],[DatePaie]])<10,"0","") & MONTH(LstMachines[[#This Row],[DatePaie]])&"-"&YEAR(LstMachines[[#This Row],[DatePaie]]) -> 10-2017 | AB13: =LstMachines[[#This Row],[DateLivr]]+1 -> 42963 | AC13: =IF(MONTH(LstMachines[[#This Row],[Distrib]])<10,"0","") & MONTH(LstMachines[[#This Row],[Distrib]]) & "-" & YEAR(LstMachines[[#This Row],[Distrib]]) -> 08-2017 | AD13: =LstMachines[[#This Row],[DateLivr]]+Délai_Vente -> 43082 | AE13: =IF(MONTH(LstMachines[[#This Row],[VteESM]])<10,"0","") & MONTH(LstMachines[[#This Row],[VteESM]]) & "-" & YEAR(LstMachines[[#This Row],[VteESM]]) -> 12-2017 | AF13: =LstMachines[[#This Row],[DateLivr]]+Rglt_à_ESMTP -> 43022 | AG13: =IF(MONTH(LstMachines[[#This Row],[RgltDistrib]])<10,"0","") & MONTH(LstMachines[[#This Row],[RgltDistrib]]) & "-" & YEAR(LstMachines[[#This Row],[RgltDistrib]]) -> 10-2017 | AH13: =LstMachines[[#This Row],[VteESM]]+Rglt_à_ESMTP -> 43142 | AI13: =IF(MONTH(LstMachines[[#This Row],[RgltVteESM]])<10,"0","") & MONTH(LstMachines[[#This Row],[RgltVteESM]]) & "-" & YEAR(LstMachines[[#This Row],[RgltVteESM]]) -> 02-2018 | AJ13: =MONTH(LstMachines[[#This Row],[DatePaie]]) -> 10 | AK13: =FIXED(YEAR(LstMachines[[#This Row],[DatePaie]]),0,TRUE) -> 2017
B14: Pelle/Chenilles | C14: ZX225 | D14: 225 | E14: ZX225USLC-6-2P-BL | F14: SETP | G14: RABASTENS | H14: 1 | I14: =IF(LstMachines[[#This Row],[Delivery]]<Début_HCME, 0, IFERROR( LstMachines[[#This Row],[Nbre]] * INDEX(TabModelSpecs[],MATCH(LstMachines[[#This Row],[Model-Spec]],TabModelSpecs[ModelSpec],0),MATCH("2018",TabModelSpecs[#Headers],0)), LstMachines[[#This Row],[Nbre]]*ROUND(AVERAGEIF(TabModelSpecs[Machine],LstMachines[[#This Row],[Model]],TabModelSpecs[Price]),0) ) ) -> 0 | J14: 42993 | K14: 5-Livrée | L14: 2017-10 ADV | N14: 42901 | O14: =MONTH(LstMachines[[#This Row],[Delivery]]) -> 9 | P14: =FIXED(YEAR(LstMachines[[#This Row],[Delivery]]),0,TRUE) -> 2017 | U14: VENTE | W14: TDA | X14: =LstMachines[[#This Row],[Delivery]] -> 42993 | Y14: =IF(MONTH(LstMachines[[#This Row],[DateLivr]])<10,"0","") & MONTH(LstMachines[[#This Row],[DateLivr]]) &"-"&YEAR(LstMachines[[#This Row],[DateLivr]]) -> 09-2017 | Z14: =LstMachines[[#This Row],[Delivery]]+Rglt_à_HCME -> 43053 | AA14: =IF(MONTH(LstMachines[[#This Row],[DatePaie]])<10,"0","") & MONTH(LstMachines[[#This Row],[DatePaie]])&"-"&YEAR(LstMachines[[#This Row],[DatePaie]]) -> 11-2017 | AB14: =LstMachines[[#This Row],[DateLivr]]+1 -> 42994 | AC14: =IF(MONTH(LstMachines[[#This Row],[Distrib]])<10,"0","") & MONTH(LstMachines[[#This Row],[Distrib]]) & "-" & YEAR(LstMachines[[#This Row],[Distrib]]) -> 09-2017 | AD14: =LstMachines[[#This Row],[DateLivr]]+Délai_Vente -> 43113 | AE14: =IF(MONTH(LstMachines[[#This Row],[VteESM]])<10,"0","") & MONTH(LstMachines[[#This Row],[VteESM]]) & "-" & YEAR(LstMachines[[#This Row],[VteESM]]) -> 01-2018 | AF14: =LstMachines[[#This Row],[DateLivr]]+Rglt_à_ESMTP -> 43053 | AG14: =IF(MONTH(LstMachines[[#This Row],[RgltDistrib]])<10,"0","") & MONTH(LstMachines[[#This Row],[RgltDistrib]]) & "-" & YEAR(LstMachines[[#This Row],[RgltDistrib]]) -> 11-2017 | AH14: =LstMachines[[#This Row],[VteESM]]+Rglt_à_ESMTP -> 43173 | AI14: =IF(MONTH(LstMachines[[#This Row],[RgltVteESM]])<10,"0","") & MONTH(LstMachines[[#This Row],[RgltVteESM]]) & "-" & YEAR(LstMachines[[#This Row],[RgltVteESM]]) -> 03-2018 | AJ14: =MONTH(LstMachines[[#This Row],[DatePaie]]) -> 11 | AK14: =FIXED(YEAR(LstMachines[[#This Row],[DatePaie]]),0,TRUE) -> 2017
B15: Mini Pelle | C15: ZX33 | D15: 33 | E15: ZX33U-5-CLR | F15: SETP | G15: RABASTENS | H15: 1 | I15: =IF(LstMachines[[#This Row],[Delivery]]<Début_HCME, 0, IFERROR( LstMachines[[#This Row],[Nbre]] * INDEX(TabModelSpecs[],MATCH(LstMachines[[#This Row],[Model-Spec]],TabModelSpecs[ModelSpec],0),MATCH("2018",TabModelSpecs[#Headers],0)), LstMachines[[#This Row],[Nbre]]*ROUND(AVERAGEIF(TabModelSpecs[Machine],LstMachines[[#This Row],[Model]],TabModelSpecs[Price]),0) ) ) -> 0 | J15: 42993 | K15: 5-Livrée | L15: 2017-10 ADV | N15: 42822 | O15: =MONTH(LstMachines[[#This Row],[Delivery]]) -> 9 | P15: =FIXED(YEAR(LstMachines[[#This Row],[Delivery]]),0,TRUE) -> 2017 | Q15: 17030057 | R15: 29000 | S15: à financer | T15: 1-04906-1 792 | U15: VENTE | V15: 4094 | W15: CITELIUM | X15: =LstMachines[[#This Row],[Delivery]] -> 42993 | Y15: =IF(MONTH(LstMachines[[#This Row],[DateLivr]])<10,"0","") & MONTH(LstMachines[[#This Row],[DateLivr]]) &"-"&YEAR(LstMachines[[#This Row],[DateLivr]]) -> 09-2017 | Z15: =LstMachines[[#This Row],[Delivery]]+Rglt_à_HCME -> 43053 | AA15: =IF(MONTH(LstMachines[[#This Row],[DatePaie]])<10,"0","") & MONTH(LstMachines[[#This Row],[DatePaie]])&"-"&YEAR(LstMachines[[#This Row],[DatePaie]]) -> 11-2017 | AB15: =LstMachines[[#This Row],[DateLivr]]+1 -> 42994 | AC15: =IF(MONTH(LstMachines[[#This Row],[Distrib]])<10,"0","") & MONTH(LstMachines[[#This Row],[Distrib]]) & "-" & YEAR(LstMachines[[#This Row],[Distrib]]) -> 09-2017 | AD15: =LstMachines[[#This Row],[DateLivr]]+Délai_Vente -> 43113 | AE15: =IF(MONTH(LstMachines[[#This Row],[VteESM]])<10,"0","") & MONTH(LstMachines[[#This Row],[VteESM]]) & "-" & YEAR(LstMachines[[#This Row],[VteESM]]) -> 01-2018 | AF15: =LstMachines[[#This Row],[DateLivr]]+Rglt_à_ESMTP -> 43053 | AG15: =IF(MONTH(LstMachines[[#This Row],[RgltDistrib]])<10,"0","") & MONTH(LstMachines[[#This Row],[RgltDistrib]]) & "-" & YEAR(LstMachines[[#This Row],[RgltDistrib]]) -> 11-2017 | AH15: =LstMachines[[#This Row],[VteESM]]+Rglt_à_ESMTP -> 43173 | AI15: =IF(MONTH(LstMachines[[#This Row],[RgltVteESM]])<10,"0","") & MONTH(LstMachines[[#This Row],[RgltVteESM]]) & "-" & YEAR(LstMachines[[#This Row],[RgltVteESM]]) -> 03-2018 | AJ15: =MONTH(LstMachines[[#This Row],[DatePaie]]) -> 11 | AK15: =FIXED(YEAR(LstMachines[[#This Row],[DatePaie]]),0,TRUE) -> 2017
B16: Pelle/Chenilles | C16: ZX85 | D16: 85 | E16: ZX85USB-5A-Mono | F16: SETP | G16: RABASTENS | H16: 1 | I16: =IF(LstMachines[[#This Row],[Delivery]]<Début_HCME, 0, IFERROR( LstMachines[[#This Row],[Nbre]] * INDEX(TabModelSpecs[],MATCH(LstMachines[[#This Row],[Model-Spec]],TabModelSpecs[ModelSpec],0),MATCH("2018",TabModelSpecs[#Headers],0)), LstMachines[[#This Row],[Nbre]]*ROUND(AVERAGEIF(TabModelSpecs[Machine],LstMachines[[#This Row],[Model]],TabModelSpecs[Price]),0) ) ) -> 0 | J16: 42993 | K16: 5-Livrée | L16: 2017-10 ADV | N16: 42975 | O16: =MONTH(LstMachines[[#This Row],[Delivery]]) -> 9 | P16: =FIXED(YEAR(LstMachines[[#This Row],[Delivery]]),0,TRUE) -> 2017 | Q16: 17080105 | R16: 56981 | U16: VENTE | V16: 4183 | W16: TEPASSO | X16: =LstMachines[[#This Row],[Delivery]] -> 42993 | Y16: =IF(MONTH(LstMachines[[#This Row],[DateLivr]])<10,"0","") & MONTH(LstMachines[[#This Row],[DateLivr]]) &"-"&YEAR(LstMachines[[#This Row],[DateLivr]]) -> 09-2017 | Z16: =LstMachines[[#This Row],[Delivery]]+Rglt_à_HCME -> 43053 | AA16: =IF(MONTH(LstMachines[[#This Row],[DatePaie]])<10,"0","") & MONTH(LstMachines[[#This Row],[DatePaie]])&"-"&YEAR(LstMachines[[#This Row],[DatePaie]]) -> 11-2017 | AB16: =LstMachines[[#This Row],[DateLivr]]+1 -> 42994 | AC16: =IF(MONTH(LstMachines[[#This Row],[Distrib]])<10,"0","") & MONTH(LstMachines[[#This Row],[Distrib]]) & "-" & YEAR(LstMachines[[#This Row],[Distrib]]) -> 09-2017 | AD16: =LstMachines[[#This Row],[DateLivr]]+Délai_Vente -> 43113 | AE16: =IF(MONTH(LstMachines[[#This Row],[VteESM]])<10,"0","") & MONTH(LstMachines[[#This Row],[VteESM]]) & "-" & YEAR(LstMachines[[#This Row],[VteESM]]) -> 01-2018 | AF16: =LstMachines[[#This Row],[DateLivr]]+Rglt_à_ESMTP -> 43053 | AG16: =IF(MONTH(LstMachines[[#This Row],[RgltDistrib]])<10,"0","") & MONTH(LstMachines[[#This Row],[RgltDistrib]]) & "-" & YEAR(LstMachines[[#This Row],[RgltDistrib]]) -> 11-2017 | AH16: =LstMachines[[#This Row],[VteESM]]+Rglt_à_ESMTP -> 43173 | AI16: =IF(MONTH(LstMachines[[#This Row],[RgltVteESM]])<10,"0","") & MONTH(LstMachines[[#This Row],[RgltVteESM]]) & "-" & YEAR(LstMachines[[#This Row],[RgltVteESM]]) -> 03-2018 | AJ16: =MONTH(LstMachines[[#This Row],[DatePaie]]) -> 11 | AK16: =FIXED(YEAR(LstMachines[[#This Row],[DatePaie]]),0,TRUE) -> 2017
B17: Pelle/Chenilles | C17: ZX300 | D17: 300 | E17: ZX300LCN-6-MN | F17: SETP | G17: RABASTENS | H17: 1 | I17: =IF(LstMachines[[#This Row],[Delivery]]<Début_HCME, 0, IFERROR( LstMachines[[#This Row],[Nbre]] * INDEX(TabModelSpecs[],MATCH(LstMachines[[#This Row],[Model-Spec]],TabModelSpecs[ModelSpec],0),MATCH("2018",TabModelSpecs[#Headers],0)), LstMachines[[#This Row],[Nbre]]*ROUND(AVERAGEIF(TabModelSpecs[Machine],LstMachines[[#This Row],[Model]],TabModelSpecs[Price]),0) ) ) -> 0 | J17: 42993 | K17: 1-Forecast | L17: 2017-05 Forecast | O17: =MONTH(LstMachines[[#This Row],[Delivery]]) -> 9 | P17: =FIXED(YEAR(LstMachines[[#This Row],[Delivery]]),0,TRUE) -> 2017 | U17: VENTE | W17: _Stock | X17: =LstMachines[[#This Row],[Delivery]] -> 42993 | Y17: =IF(MONTH(LstMachines[[#This Row],[DateLivr]])<10,"0","") & MONTH(LstMachines[[#This Row],[DateLivr]]) &"-"&YEAR(LstMachines[[#This Row],[DateLivr]]) -> 09-2017 | Z17: =LstMachines[[#This Row],[Delivery]]+Rglt_à_HCME -> 43053 | AA17: =IF(MONTH(LstMachines[[#This Row],[DatePaie]])<10,"0","") & MONTH(LstMachines[[#This Row],[DatePaie]])&"-"&YEAR(LstMachines[[#This Row],[DatePaie]]) -> 11-2017 | AB17: =LstMachines[[#This Row],[DateLivr]]+1 -> 42994 | AC17: =IF(MONTH(LstMachines[[#This Row],[Distrib]])<10,"0","") & MONTH(LstMachines[[#This Row],[Distrib]]) & "-" & YEAR(LstMachines[[#This Row],[Distrib]]) -> 09-2017 | AD17: =LstMachines[[#This Row],[DateLivr]]+Délai_Vente -> 43113 | AE17: =IF(MONTH(LstMachines[[#This Row],[VteESM]])<10,"0","") & MONTH(LstMachines[[#This Row],[VteESM]]) & "-" & YEAR(LstMachines[[#This Row],[VteESM]]) -> 01-2018 | AF17: =LstMachines[[#This Row],[DateLivr]]+Rglt_à_ESMTP -> 43053 | AG17: =IF(MONTH(LstMachines[[#This Row],[RgltDistrib]])<10,"0","") & MONTH(LstMachines[[#This Row],[RgltDistrib]]) & "-" & YEAR(LstMachines[[#This Row],[RgltDistrib]]) -> 11-2017 | AH17: =LstMachines[[#This Row],[VteESM]]+Rglt_à_ESMTP -> 43173 | AI17: =IF(MONTH(LstMachines[[#This Row],[RgltVteESM]])<10,"0","") & MONTH(LstMachines[[#This Row],[RgltVteESM]]) & "-" & YEAR(LstMachines[[#This Row],[RgltVteESM]]) -> 03-2018 | AJ17: =MONTH(LstMachines[[#This Row],[DatePaie]]) -> 11 | AK17: =FIXED(YEAR(LstMachines[[#This Row],[DatePaie]]),0,TRUE) -> 2017
B18: Pelle/Pneus | C18: ZX145 | D18: 145 | E18: ZX145W-6-2P | F18: SETP | G18: RABASTENS | H18: 1 | I18: =IF(LstMachines[[#This Row],[Delivery]]<Début_HCME, 0, IFERROR( LstMachines[[#This Row],[Nbre]] * INDEX(TabModelSpecs[],MATCH(LstMachines[[#This Row],[Model-Spec]],TabModelSpecs[ModelSpec],0),MATCH("2018",TabModelSpecs[#Headers],0)), LstMachines[[#This Row],[Nbre]]*ROUND(AVERAGEIF(TabModelSpecs[Machine],LstMachines[[#This Row],[Model]],TabModelSpecs[Price]),0) ) ) -> 0 | J18: 42993 | K18: ** Lost ** | L18: 2017-10 ADV | M18: ** Lost ** | N18: 42979 | O18: =MONTH(LstMachines[[#This Row],[Delivery]]) -> 9 | P18: =FIXED(YEAR(LstMachines[[#This Row],[Delivery]]),0,TRUE) -> 2017 | X18: =LstMachines[[#This Row],[Delivery]] -> 42993 | Y18: =IF(MONTH(LstMachines[[#This Row],[DateLivr]])<10,"0","") & MONTH(LstMachines[[#This Row],[DateLivr]]) &"-"&YEAR(LstMachines[[#This Row],[DateLivr]]) -> 09-2017 | Z18: =LstMachines[[#This Row],[Delivery]]+Rglt_à_HCME -> 43053 | AA18: =IF(MONTH(LstMachines[[#This Row],[DatePaie]])<10,"0","") & MONTH(LstMachines[[#This Row],[DatePaie]])&"-"&YEAR(LstMachines[[#This Row],[DatePaie]]) -> 11-2017 | AB18: =LstMachines[[#This Row],[DateLivr]]+1 -> 42994 | AC18: =IF(MONTH(LstMachines[[#This Row],[Distrib]])<10,"0","") & MONTH(LstMachines[[#This Row],[Distrib]]) & "-" & YEAR(LstMachines[[#This Row],[Distrib]]) -> 09-2017 | AD18: =LstMachines[[#This Row],[DateLivr]]+Délai_Vente -> 43113 | AE18: =IF(MONTH(LstMachines[[#This Row],[VteESM]])<10,"0","") & MONTH(LstMachines[[#This Row],[VteESM]]) & "-" & YEAR(LstMachines[[#This Row],[VteESM]]) -> 01-2018 | AF18: =LstMachines[[#This Row],[DateLivr]]+Rglt_à_ESMTP -> 43053 | AG18: =IF(MONTH(LstMachines[[#This Row],[RgltDistrib]])<10,"0","") & MONTH(LstMachines[[#This Row],[RgltDistrib]]) & "-" & YEAR(LstMachines[[#This Row],[RgltDistrib]]) -> 11-2017 | AH18: =LstMachines[[#This Row],[VteESM]]+Rglt_à_ESMTP -> 43173 | AI18: =IF(MONTH(LstMachines[[#This Row],[RgltVteESM]])<10,"0","") & MONTH(LstMachines[[#This Row],[RgltVteESM]]) & "-" & YEAR(LstMachines[[#This Row],[RgltVteESM]]) -> 03-2018 | AJ18: =MONTH(LstMachines[[#This Row],[DatePaie]]) -> 11 | AK18: =FIXED(YEAR(LstMachines[[#This Row],[DatePaie]]),0,TRUE) -> 2017
B19: Mini Pelle | C19: ZX65 | D19: 65 | E19: ZX65USB-5-CLP | F19: SETP | G19: RABASTENS | H19: 1 | I19: =IF(LstMachines[[#This Row],[Delivery]]<Début_HCME, 0, IFERROR( LstMachines[[#This Row],[Nbre]] * INDEX(TabModelSpecs[],MATCH(LstMachines[[#This Row],[Model-Spec]],TabModelSpecs[ModelSpec],0),MATCH("2018",TabModelSpecs[#Headers],0)), LstMachines[[#This Row],[Nbre]]*ROUND(AVERAGEIF(TabModelSpecs[Machine],LstMachines[[#This Row],[Model]],TabModelSpecs[Price]),0) ) ) -> 0 | J19: 43023 | K19: 5-Livrée | L19: 2017-10 ADV | M19: REGULARISER STE SUR REGIE (setp) | N19: 42975 | O19: =MONTH(LstMachines[[#This Row],[Delivery]]) -> 10 | P19: =FIXED(YEAR(LstMachines[[#This Row],[Delivery]]),0,TRUE) -> 2017 | Q19: 16080003 | U19: VENTE | V19: 3959 | W19: SANCHEZ | X19: =LstMachines[[#This Row],[Delivery]] -> 43023 | Y19: =IF(MONTH(LstMachines[[#This Row],[DateLivr]])<10,"0","") & MONTH(LstMachines[[#This Row],[DateLivr]]) &"-"&YEAR(LstMachines[[#This Row],[DateLivr]]) -> 10-2017 | Z19: =LstMachines[[#This Row],[Delivery]]+Rglt_à_HCME -> 43083 | AA19: =IF(MONTH(LstMachines[[#This Row],[DatePaie]])<10,"0","") & MONTH(LstMachines[[#This Row],[DatePaie]])&"-"&YEAR(LstMachines[[#This Row],[DatePaie]]) -> 12-2017 | AB19: =LstMachines[[#This Row],[DateLivr]]+1 -> 43024 | AC19: =IF(MONTH(LstMachines[[#This Row],[Distrib]])<10,"0","") & MONTH(LstMachines[[#This Row],[Distrib]]) & "-" & YEAR(LstMachines[[#This Row],[Distrib]]) -> 10-2017 | AD19: =LstMachines[[#This Row],[DateLivr]]+Délai_Vente -> 43143 | AE19: =IF(MONTH(LstMachines[[#This Row],[VteESM]])<10,"0","") & MONTH(LstMachines[[#This Row],[VteESM]]) & "-" & YEAR(LstMachines[[#This Row],[VteESM]]) -> 02-2018 | AF19: =LstMachines[[#This Row],[DateLivr]]+Rglt_à_ESMTP -> 43083 | AG19: =IF(MONTH(LstMachines[[#This Row],[RgltDistrib]])<10,"0","") & MONTH(LstMachines[[#This Row],[RgltDistrib]]) & "-" & YEAR(LstMachines[[#This Row],[RgltDistrib]]) -> 12-2017 | AH19: =LstMachines[[#This Row],[VteESM]]+Rglt_à_ESMTP -> 43203 | AI19: =IF(MONTH(LstMachines[[#This Row],[RgltVteESM]])<10,"0","") & MONTH(LstMachines[[#This Row],[RgltVteESM]]) & "-" & YEAR(LstMachines[[#This Row],[RgltVteESM]]) -> 04-2018 | AJ19: =MONTH(LstMachines[[#This Row],[DatePaie]]) -> 12 | AK19: =FIXED(YEAR(LstMachines[[#This Row],[DatePaie]]),0,TRUE) -> 2017
B20: Pelle/Chenilles | C20: ZX85 | D20: 85 | E20: ZX85USB-5A-Mono | F20: SETP | G20: RABASTENS | H20: 1 | I20: =IF(LstMachines[[#This Row],[Delivery]]<Début_HCME, 0, IFERROR( LstMachines[[#This Row],[Nbre]] * INDEX(TabModelSpecs[],MATCH(LstMachines[[#This Row],[Model-Spec]],TabModelSpecs[ModelSpec],0),MATCH("2018",TabModelSpecs[#Headers],0)), LstMachines[[#This Row],[Nbre]]*ROUND(AVERAGEIF(TabModelSpecs[Machine],LstMachines[[#This Row],[Model]],TabModelSpecs[Price]),0) ) ) -> 0 | J20: 43023 | K20: 5-Livrée | L20: 2017-10 ADV | N20: 42822 | O20: =MONTH(LstMachines[[#This Row],[Delivery]]) -> 10 | P20: =FIXED(YEAR(LstMachines[[#This Row],[Delivery]]),0,TRUE) -> 2017 | Q20: 17030033 | R20: 52800 | U20: VENTE | V20: 4086 | W20: GINESTE | X20: =LstMachines[[#This Row],[Delivery]] -> 43023 | Y20: =IF(MONTH(LstMachines[[#This Row],[DateLivr]])<10,"0","") & MONTH(LstMachines[[#This Row],[DateLivr]]) &"-"&YEAR(LstMachines[[#This Row],[DateLivr]]) -> 10-2017 | Z20: =LstMachines[[#This Row],[Delivery]]+Rglt_à_HCME -> 43083 | AA20: =IF(MONTH(LstMachines[[#This Row],[DatePaie]])<10,"0","") & MONTH(LstMachines[[#This Row],[DatePaie]])&"-"&YEAR(LstMachines[[#This Row],[DatePaie]]) -> 12-2017 | AB20: =LstMachines[[#This Row],[DateLivr]]+1 -> 43024 | AC20: =IF(MONTH(LstMachines[[#This Row],[Distrib]])<10,"0","") & MONTH(LstMachines[[#This Row],[Distrib]]) & "-" & YEAR(LstMachines[[#This Row],[Distrib]]) -> 10-2017 | AD20: =LstMachines[[#This Row],[DateLivr]]+Délai_Vente -> 43143 | AE20: =IF(MONTH(LstMachines[[#This Row],[VteESM]])<10,"0","") & MONTH(LstMachines[[#This Row],[VteESM]]) & "-" & YEAR(LstMachines[[#This Row],[VteESM]]) -> 02-2018 | AF20: =LstMachines[[#This Row],[DateLivr]]+Rglt_à_ESMTP -> 43083 | AG20: =IF(MONTH(LstMachines[[#This Row],[RgltDistrib]])<10,"0","") & MONTH(LstMachines[[#This Row],[RgltDistrib]]) & "-" & YEAR(LstMachines[[#This Row],[RgltDistrib]]) -> 12-2017 | AH20: =LstMachines[[#This Row],[VteESM]]+Rglt_à_ESMTP -> 43203 | AI20: =IF(MONTH(LstMachines[[#This Row],[RgltVteESM]])<10,"0","") & MONTH(LstMachines[[#This Row],[RgltVteESM]]) & "-" & YEAR(LstMachines[[#This Row],[RgltVteESM]]) -> 04-2018 | AJ20: =MONTH(LstMachines[[#This Row],[DatePaie]]) -> 12 | AK20: =FIXED(YEAR(LstMachines[[#This Row],[DatePaie]]),0,TRUE) -> 2017
B21: Mini Pelle | C21: ZX26 | D21: 26 | E21: ZX26U-5-CLR | F21: SETP | G21: LÉZIGNAN | H21: 1 | I21: =IF(LstMachines[[#This Row],[Delivery]]<Début_HCME, 0, IFERROR( LstMachines[[#This Row],[Nbre]] * INDEX(TabModelSpecs[],MATCH(LstMachines[[#This Row],[Model-Spec]],TabModelSpecs[ModelSpec],0),MATCH("2018",TabModelSpecs[#Headers],0)), LstMachines[[#This Row],[Nbre]]*ROUND(AVERAGEIF(TabModelSpecs[Machine],LstMachines[[#This Row],[Model]],TabModelSpecs[Price]),0) ) ) -> 0 | J21: 43023 | K21: 5-Livrée | L21: 2017-12-06 ADV | M21: livrée directement à Lezignan | N21: 42914 | O21: =MONTH(LstMachines[[#This Row],[Delivery]]) -> 10 | P21: =FIXED(YEAR(LstMachines[[#This Row],[Delivery]]),0,TRUE) -> 2017 | Q21: 17060095 | R21: 22700 | T21: 1-04964-1 794 | U21: VENTE | V21: 4148 | W21: SAS SRI TRAL | X21: =LstMachines[[#This Row],[Delivery]] -> 43023 | Y21: =IF(MONTH(LstMachines[[#This Row],[DateLivr]])<10,"0","") & MONTH(LstMachines[[#This Row],[DateLivr]]) &"-"&YEAR(LstMachines[[#This Row],[DateLivr]]) -> 10-2017 | Z21: =LstMachines[[#This Row],[Delivery]]+Rglt_à_HCME -> 43083 | AA21: =IF(MONTH(LstMachines[[#This Row],[DatePaie]])<10,"0","") & MONTH(LstMachines[[#This Row],[DatePaie]])&"-"&YEAR(LstMachines[[#This Row],[DatePaie]]) -> 12-2017 | AB21: =LstMachines[[#This Row],[DateLivr]]+1 -> 43024 | AC21: =IF(MONTH(LstMachines[[#This Row],[Distrib]])<10,"0","") & MONTH(LstMachines[[#This Row],[Distrib]]) & "-" & YEAR(LstMachines[[#This Row],[Distrib]]) -> 10-2017 | AD21: =LstMachines[[#This Row],[DateLivr]]+Délai_Vente -> 43143 | AE21: =IF(MONTH(LstMachines[[#This Row],[VteESM]])<10,"0","") & MONTH(LstMachines[[#This Row],[VteESM]]) & "-" & YEAR(LstMachines[[#This Row],[VteESM]]) -> 02-2018 | AF21: =LstMachines[[#This Row],[DateLivr]]+Rglt_à_ESMTP -> 43083 | AG21: =IF(MONTH(LstMachines[[#This Row],[RgltDistrib]])<10,"0","") & MONTH(LstMachines[[#This Row],[RgltDistrib]]) & "-" & YEAR(LstMachines[[#This Row],[RgltDistrib]]) -> 12-2017 | AH21: =LstMachines[[#This Row],[VteESM]]+Rglt_à_ESMTP -> 43203 | AI21: =IF(MONTH(LstMachines[[#This Row],[RgltVteESM]])<10,"0","") & MONTH(LstMachines[[#This Row],[RgltVteESM]]) & "-" & YEAR(LstMachines[[#This Row],[RgltVteESM]]) -> 04-2018 | AJ21: =MONTH(LstMachines[[#This Row],[DatePaie]]) -> 12 | AK21: =FIXED(YEAR(LstMachines[[#This Row],[DatePaie]]),0,TRUE) -> 2017
B22: Mini Pelle | C22: ZX19 | D22: 19 | E22: ZX19U-5 | F22: BTPS | G22: ORTHEZ | H22: 1 | I22: =IF(LstMachines[[#This Row],[Delivery]]<Début_HCME, 0, IFERROR( LstMachines[[#This Row],[Nbre]] * INDEX(TabModelSpecs[],MATCH(LstMachines[[#This Row],[Model-Spec]],TabModelSpecs[ModelSpec],0),MATCH("2018",TabModelSpecs[#Headers],0)), LstMachines[[#This Row],[Nbre]]*ROUND(AVERAGEIF(TabModelSpecs[Machine],LstMachines[[#This Row],[Model]],TabModelSpecs[Price]),0) ) ) -> 0 | J22: 43054 | K22: 3-Commande | L22: 2017-11 BTPS | O22: =MONTH(LstMachines[[#This Row],[Delivery]]) -> 11 | P22: =FIXED(YEAR(LstMachines[[#This Row],[Delivery]]),0,TRUE) -> 2017 | X22: =LstMachines[[#This Row],[Delivery]] -> 43054 | Y22: =IF(MONTH(LstMachines[[#This Row],[DateLivr]])<10,"0","") & MONTH(LstMachines[[#This Row],[DateLivr]]) &"-"&YEAR(LstMachines[[#This Row],[DateLivr]]) -> 11-2017 | Z22: =LstMachines[[#This Row],[Delivery]]+Rglt_à_HCME -> 43114 | AA22: =IF(MONTH(LstMachines[[#This Row],[DatePaie]])<10,"0","") & MONTH(LstMachines[[#This Row],[DatePaie]])&"-"&YEAR(LstMachines[[#This Row],[DatePaie]]) -> 01-2018 | AB22: =LstMachines[[#This Row],[DateLivr]]+1 -> 43055 | AC22: =IF(MONTH(LstMachines[[#This Row],[Distrib]])<10,"0","") & MONTH(LstMachines[[#This Row],[Distrib]]) & "-" & YEAR(LstMachines[[#This Row],[Distrib]]) -> 11-2017 | AD22: =LstMachines[[#This Row],[DateLivr]]+Délai_Vente -> 43174 | AE22: =IF(MONTH(LstMachines[[#This Row],[VteESM]])<10,"0","") & MONTH(LstMachines[[#This Row],[VteESM]]) & "-" & YEAR(LstMachines[[#This Row],[VteESM]]) -> 03-2018 | AF22: =LstMachines[[#This Row],[DateLivr]]+Rglt_à_ESMTP -> 43114 | AG22: =IF(MONTH(LstMachines[[#This Row],[RgltDistrib]])<10,"0","") & MONTH(LstMachines[[#This Row],[RgltDistrib]]) & "-" & YEAR(LstMachines[[#This Row],[RgltDistrib]]) -> 01-2018 | AH22: =LstMachines[[#This Row],[VteESM]]+Rglt_à_ESMTP -> 43234 | AI22: =IF(MONTH(LstMachines[[#This Row],[RgltVteESM]])<10,"0","") & MONTH(LstMachines[[#This Row],[RgltVteESM]]) & "-" & YEAR(LstMachines[[#This Row],[RgltVteESM]]) -> 05-2018 | AJ22: =MONTH(LstMachines[[#This Row],[DatePaie]]) -> 1 | AK22: =FIXED(YEAR(LstMachines[[#This Row],[DatePaie]]),0,TRUE) -> 2018
B23: Mini Pelle | C23: ZX26 | D23: 26 | E23: ZX26U-5-YLR | F23: BTPS | G23: ORTHEZ | H23: 1 | I23: =IF(LstMachines[[#This Row],[Delivery]]<Début_HCME, 0, IFERROR( LstMachines[[#This Row],[Nbre]] * INDEX(TabModelSpecs[],MATCH(LstMachines[[#This Row],[Model-Spec]],TabModelSpecs[ModelSpec],0),MATCH("2018",TabModelSpecs[#Headers],0)), LstMachines[[#This Row],[Nbre]]*ROUND(AVERAGEIF(TabModelSpecs[Machine],LstMachines[[#This Row],[Model]],TabModelSpecs[Price]),0) ) ) -> 0 | J23: 43054 | K23: 3-Commande | L23: 2017-11 BTPS | O23: =MONTH(LstMachines[[#This Row],[Delivery]]) -> 11 | P23: =FIXED(YEAR(LstMachines[[#This Row],[Delivery]]),0,TRUE) -> 2017 | X23: =LstMachines[[#This Row],[Delivery]] -> 43054 | Y23: =IF(MONTH(LstMachines[[#This Row],[DateLivr]])<10,"0","") & MONTH(LstMachines[[#This Row],[DateLivr]]) &"-"&YEAR(LstMachines[[#This Row],[DateLivr]]) -> 11-2017 | Z23: =LstMachines[[#This Row],[Delivery]]+Rglt_à_HCME -> 43114 | AA23: =IF(MONTH(LstMachines[[#This Row],[DatePaie]])<10,"0","") & MONTH(LstMachines[[#This Row],[DatePaie]])&"-"&YEAR(LstMachines[[#This Row],[DatePaie]]) -> 01-2018 | AB23: =LstMachines[[#This Row],[DateLivr]]+1 -> 43055 | AC23: =IF(MONTH(LstMachines[[#This Row],[Distrib]])<10,"0","") & MONTH(LstMachines[[#This Row],[Distrib]]) & "-" & YEAR(LstMachines[[#This Row],[Distrib]]) -> 11-2017 | AD23: =LstMachines[[#This Row],[DateLivr]]+Délai_Vente -> 43174 | AE23: =IF(MONTH(LstMachines[[#This Row],[VteESM]])<10,"0","") & MONTH(LstMachines[[#This Row],[VteESM]]) & "-" & YEAR(LstMachines[[#This Row],[VteESM]]) -> 03-2018 | AF23: =LstMachines[[#This Row],[DateLivr]]+Rglt_à_ESMTP -> 43114 | AG23: =IF(MONTH(LstMachines[[#This Row],[RgltDistrib]])<10,"0","") & MONTH(LstMachines[[#This Row],[RgltDistrib]]) & "-" & YEAR(LstMachines[[#This Row],[RgltDistrib]]) -> 01-2018 | AH23: =LstMachines[[#This Row],[VteESM]]+Rglt_à_ESMTP -> 43234 | AI23: =IF(MONTH(LstMachines[[#This Row],[RgltVteESM]])<10,"0","") & MONTH(LstMachines[[#This Row],[RgltVteESM]]) & "-" & YEAR(LstMachines[[#This Row],[RgltVteESM]]) -> 05-2018 | AJ23: =MONTH(LstMachines[[#This Row],[DatePaie]]) -> 1 | AK23: =FIXED(YEAR(LstMachines[[#This Row],[DatePaie]]),0,TRUE) -> 2018
B24: Pelle/Chenilles | C24: ZX350 | D24: 350 | E24: ZX350LCN-6-MN | F24: BTPS | G24: ORTHEZ | H24: 1 | I24: =IF(LstMachines[[#This Row],[Delivery]]<Début_HCME, 0, IFERROR( LstMachines[[#This Row],[Nbre]] * INDEX(TabModelSpecs[],MATCH(LstMachines[[#This Row],[Model-Spec]],TabModelSpecs[ModelSpec],0),MATCH("2018",TabModelSpecs[#Headers],0)), LstMachines[[#This Row],[Nbre]]*ROUND(AVERAGEIF(TabModelSpecs[Machine],LstMachines[[#This Row],[Model]],TabModelSpecs[Price]),0) ) ) -> 0 | J24: 43054 | K24: 3-Commande | L24: 2017-11 BTPS | O24: =MONTH(LstMachines[[#This Row],[Delivery]]) -> 11 | P24: =FIXED(YEAR(LstMachines[[#This Row],[Delivery]]),0,TRUE) -> 2017 | X24: =LstMachines[[#This Row],[Delivery]] -> 43054 | Y24: =IF(MONTH(LstMachines[[#This Row],[DateLivr]])<10,"0","") & MONTH(LstMachines[[#This Row],[DateLivr]]) &"-"&YEAR(LstMachines[[#This Row],[DateLivr]]) -> 11-2017 | Z24: =LstMachines[[#This Row],[Delivery]]+Rglt_à_HCME -> 43114 | AA24: =IF(MONTH(LstMachines[[#This Row],[DatePaie]])<10,"0","") & MONTH(LstMachines[[#This Row],[DatePaie]])&"-"&YEAR(LstMachines[[#This Row],[DatePaie]]) -> 01-2018 | AB24: =LstMachines[[#This Row],[DateLivr]]+1 -> 43055 | AC24: =IF(MONTH(LstMachines[[#This Row],[Distrib]])<10,"0","") & MONTH(LstMachines[[#This Row],[Distrib]]) & "-" & YEAR(LstMachines[[#This Row],[Distrib]]) -> 11-2017 | AD24: =LstMachines[[#This Row],[DateLivr]]+Délai_Vente -> 43174 | AE24: =IF(MONTH(LstMachines[[#This Row],[VteESM]])<10,"0","") & MONTH(LstMachines[[#This Row],[VteESM]]) & "-" & YEAR(LstMachines[[#This Row],[VteESM]]) -> 03-2018 | AF24: =LstMachines[[#This Row],[DateLivr]]+Rglt_à_ESMTP -> 43114 | AG24: =IF(MONTH(LstMachines[[#This Row],[RgltDistrib]])<10,"0","") & MONTH(LstMachines[[#This Row],[RgltDistrib]]) & "-" & YEAR(LstMachines[[#This Row],[RgltDistrib]]) -> 01-2018 | AH24: =LstMachines[[#This Row],[VteESM]]+Rglt_à_ESMTP -> 43234 | AI24: =IF(MONTH(LstMachines[[#This Row],[RgltVteESM]])<10,"0","") & MONTH(LstMachines[[#This Row],[RgltVteESM]]) & "-" & YEAR(LstMachines[[#This Row],[RgltVteESM]]) -> 05-2018 | AJ24: =MONTH(LstMachines[[#This Row],[DatePaie]]) -> 1 | AK24: =FIXED(YEAR(LstMachines[[#This Row],[DatePaie]]),0,TRUE) -> 2018
B25: Pelle/Chenilles | C25: ZX490 | D25: 490 | E25: ZX490-6-BE | F25: BTPS | G25: ORTHEZ | H25: 1 | I25: =IF(LstMachines[[#This Row],[Delivery]]<Début_HCME, 0, IFERROR( LstMachines[[#This Row],[Nbre]] * INDEX(TabModelSpecs[],MATCH(LstMachines[[#This Row],[Model-Spec]],TabModelSpecs[ModelSpec],0),MATCH("2018",TabModelSpecs[#Headers],0)), LstMachines[[#This Row],[Nbre]]*ROUND(AVERAGEIF(TabModelSpecs[Machine],LstMachines[[#This Row],[Model]],TabModelSpecs[Price]),0) ) ) -> 0 | J25: 43054 | K25: 3-Commande | L25: 2017-11 BTPS | O25: =MONTH(LstMachines[[#This Row],[Delivery]]) -> 11 | P25: =FIXED(YEAR(LstMachines[[#This Row],[Delivery]]),0,TRUE) -> 2017 | X25: =LstMachines[[#This Row],[Delivery]] -> 43054 | Y25: =IF(MONTH(LstMachines[[#This Row],[DateLivr]])<10,"0","") & MONTH(LstMachines[[#This Row],[DateLivr]]) &"-"&YEAR(LstMachines[[#This Row],[DateLivr]]) -> 11-2017 | Z25: =LstMachines[[#This Row],[Delivery]]+Rglt_à_HCME -> 43114 | AA25: =IF(MONTH(LstMachines[[#This Row],[DatePaie]])<10,"0","") & MONTH(LstMachines[[#This Row],[DatePaie]])&"-"&YEAR(LstMachines[[#This Row],[DatePaie]]) -> 01-2018 | AB25: =LstMachines[[#This Row],[DateLivr]]+1 -> 43055 | AC25: =IF(MONTH(LstMachines[[#This Row],[Distrib]])<10,"0","") & MONTH(LstMachines[[#This Row],[Distrib]]) & "-" & YEAR(LstMachines[[#This Row],[Distrib]]) -> 11-2017 | AD25: =LstMachines[[#This Row],[DateLivr]]+Délai_Vente -> 43174 | AE25: =IF(MONTH(LstMachines[[#This Row],[VteESM]])<10,"0","") & MONTH(LstMachines[[#This Row],[VteESM]]) & "-" & YEAR(LstMachines[[#This Row],[VteESM]]) -> 03-2018 | AF25: =LstMachines[[#This Row],[DateLivr]]+Rglt_à_ESMTP -> 43114 | AG25: =IF(MONTH(LstMachines[[#This Row],[RgltDistrib]])<10,"0","") & MONTH(LstMachines[[#This Row],[RgltDistrib]]) & "-" & YEAR(LstMachines[[#This Row],[RgltDistrib]]) -> 01-2018 | AH25: =LstMachines[[#This Row],[VteESM]]+Rglt_à_ESMTP -> 43234 | AI25: =IF(MONTH(LstMachines[[#This Row],[RgltVteESM]])<10,"0","") & MONTH(LstMachines[[#This Row],[RgltVteESM]]) & "-" & YEAR(LstMachines[[#This Row],[RgltVteESM]]) -> 05-2018 | AJ25: =MONTH(LstMachines[[#This Row],[DatePaie]]) -> 1 | AK25: =FIXED(YEAR(LstMachines[[#This Row],[DatePaie]]),0,TRUE) -> 2018
B26: Mini Pelle | C26: ZX65 | D26: 65 | E26: ZX65USB-5-CLRNH | F26: BTPS | G26: ORTHEZ | H26: 1 | I26: =IF(LstMachines[[#This Row],[Delivery]]<Début_HCME, 0, IFERROR( LstMachines[[#This Row],[Nbre]] * INDEX(TabModelSpecs[],MATCH(LstMachines[[#This Row],[Model-Spec]],TabModelSpecs[ModelSpec],0),MATCH("2018",TabModelSpecs[#Headers],0)), LstMachines[[#This Row],[Nbre]]*ROUND(AVERAGEIF(TabModelSpecs[Machine],LstMachines[[#This Row],[Model]],TabModelSpecs[Price]),0) ) ) -> 0 | J26: 43054 | K26: 3-Commande | L26: 2017-11 BTPS | O26: =MONTH(LstMachines[[#This Row],[Delivery]]) -> 11 | P26: =FIXED(YEAR(LstMachines[[#This Row],[Delivery]]),0,TRUE) -> 2017 | X26: =LstMachines[[#This Row],[Delivery]] -> 43054 | Y26: =IF(MONTH(LstMachines[[#This Row],[DateLivr]])<10,"0","") & MONTH(LstMachines[[#This Row],[DateLivr]]) &"-"&YEAR(LstMachines[[#This Row],[DateLivr]]) -> 11-2017 | Z26: =LstMachines[[#This Row],[Delivery]]+Rglt_à_HCME -> 43114 | AA26: =IF(MONTH(LstMachines[[#This Row],[DatePaie]])<10,"0","") & MONTH(LstMachines[[#This Row],[DatePaie]])&"-"&YEAR(LstMachines[[#This Row],[DatePaie]]) -> 01-2018 | AB26: =LstMachines[[#This Row],[DateLivr]]+1 -> 43055 | AC26: =IF(MONTH(LstMachines[[#This Row],[Distrib]])<10,"0","") & MONTH(LstMachines[[#This Row],[Distrib]]) & "-" & YEAR(LstMachines[[#This Row],[Distrib]]) -> 11-2017 | AD26: =LstMachines[[#This Row],[DateLivr]]+Délai_Vente -> 43174 | AE26: =IF(MONTH(LstMachines[[#This Row],[VteESM]])<10,"0","") & MONTH(LstMachines[[#This Row],[VteESM]]) & "-" & YEAR(LstMachines[[#This Row],[VteESM]]) -> 03-2018 | AF26: =LstMachines[[#This Row],[DateLivr]]+Rglt_à_ESMTP -> 43114 | AG26: =IF(MONTH(LstMachines[[#This Row],[RgltDistrib]])<10,"0","") & MONTH(LstMachines[[#This Row],[RgltDistrib]]) & "-" & YEAR(LstMachines[[#This Row],[RgltDistrib]]) -> 01-2018 | AH26: =LstMachines[[#This Row],[VteESM]]+Rglt_à_ESMTP -> 43234 | AI26: =IF(MONTH(LstMachines[[#This Row],[RgltVteESM]])<10,"0","") & MONTH(LstMachines[[#This Row],[RgltVteESM]]) & "-" & YEAR(LstMachines[[#This Row],[RgltVteESM]]) -> 05-2018 | AJ26: =MONTH(LstMachines[[#This Row],[DatePaie]]) -> 1 | AK26: =FIXED(YEAR(LstMachines[[#This Row],[DatePaie]]),0,TRUE) -> 2018
B27: Mini Pelle | C27: ZX65 | D27: 65 | E27: ZX65USB-5-CLRNH | F27: BTPS | G27: ORTHEZ | H27: 1 | I27: =IF(LstMachines[[#This Row],[Delivery]]<Début_HCME, 0, IFERROR( LstMachines[[#This Row],[Nbre]] * INDEX(TabModelSpecs[],MATCH(LstMachines[[#This Row],[Model-Spec]],TabModelSpecs[ModelSpec],0),MATCH("2018",TabModelSpecs[#Headers],0)), LstMachines[[#This Row],[Nbre]]*ROUND(AVERAGEIF(TabModelSpecs[Machine],LstMachines[[#This Row],[Model]],TabModelSpecs[Price]),0) ) ) -> 0 | J27: 43054 | K27: 3-Commande | L27: 2017-11 BTPS | O27: =MONTH(LstMachines[[#This Row],[Delivery]]) -> 11 | P27: =FIXED(YEAR(LstMachines[[#This Row],[Delivery]]),0,TRUE) -> 2017 | X27: =LstMachines[[#This Row],[Delivery]] -> 43054 | Y27: =IF(MONTH(LstMachines[[#This Row],[DateLivr]])<10,"0","") & MONTH(LstMachines[[#This Row],[DateLivr]]) &"-"&YEAR(LstMachines[[#This Row],[DateLivr]]) -> 11-2017 | Z27: =LstMachines[[#This Row],[Delivery]]+Rglt_à_HCME -> 43114 | AA27: =IF(MONTH(LstMachines[[#This Row],[DatePaie]])<10,"0","") & MONTH(LstMachines[[#This Row],[DatePaie]])&"-"&YEAR(LstMachines[[#This Row],[DatePaie]]) -> 01-2018 | AB27: =LstMachines[[#This Row],[DateLivr]]+1 -> 43055 | AC27: =IF(MONTH(LstMachines[[#This Row],[Distrib]])<10,"0","") & MONTH(LstMachines[[#This Row],[Distrib]]) & "-" & YEAR(LstMachines[[#This Row],[Distrib]]) -> 11-2017 | AD27: =LstMachines[[#This Row],[DateLivr]]+Délai_Vente -> 43174 | AE27: =IF(MONTH(LstMachines[[#This Row],[VteESM]])<10,"0","") & MONTH(LstMachines[[#This Row],[VteESM]]) & "-" & YEAR(LstMachines[[#This Row],[VteESM]]) -> 03-2018 | AF27: =LstMachines[[#This Row],[DateLivr]]+Rglt_à_ESMTP -> 43114 | AG27: =IF(MONTH(LstMachines[[#This Row],[RgltDistrib]])<10,"0","") & MONTH(LstMachines[[#This Row],[RgltDistrib]]) & "-" & YEAR(LstMachines[[#This Row],[RgltDistrib]]) -> 01-2018 | AH27: =LstMachines[[#This Row],[VteESM]]+Rglt_à_ESMTP -> 43234 | AI27: =IF(MONTH(LstMachines[[#This Row],[RgltVteESM]])<10,"0","") & MONTH(LstMachines[[#This Row],[RgltVteESM]]) & "-" & YEAR(LstMachines[[#This Row],[RgltVteESM]]) -> 05-2018 | AJ27: =MONTH(LstMachines[[#This Row],[DatePaie]]) -> 1 | AK27: =FIXED(YEAR(LstMachines[[#This Row],[DatePaie]]),0,TRUE) -> 2018
B28: Mini Pelle | C28: ZX65 | D28: 65 | E28: ZX65USB-5-CLRNH | F28: BTPS | G28: ORTHEZ | H28: 1 | I28: =IF(LstMachines[[#This Row],[Delivery]]<Début_HCME, 0, IFERROR( LstMachines[[#This Row],[Nbre]] * INDEX(TabModelSpecs[],MATCH(LstMachines[[#This Row],[Model-Spec]],TabModelSpecs[ModelSpec],0),MATCH("2018",TabModelSpecs[#Headers],0)), LstMachines[[#This Row],[Nbre]]*ROUND(AVERAGEIF(TabModelSpecs[Machine],LstMachines[[#This Row],[Model]],TabModelSpecs[Price]),0) ) ) -> 0 | J28: 43054 | K28: 3-Commande | L28: 2017-11 BTPS | O28: =MONTH(LstMachines[[#This Row],[Delivery]]) -> 11 | P28: =FIXED(YEAR(LstMachines[[#This Row],[Delivery]]),0,TRUE) -> 2017 | X28: =LstMachines[[#This Row],[Delivery]] -> 43054 | Y28: =IF(MONTH(LstMachines[[#This Row],[DateLivr]])<10,"0","") & MONTH(LstMachines[[#This Row],[DateLivr]]) &"-"&YEAR(LstMachines[[#This Row],[DateLivr]]) -> 11-2017 | Z28: =LstMachines[[#This Row],[Delivery]]+Rglt_à_HCME -> 43114 | AA28: =IF(MONTH(LstMachines[[#This Row],[DatePaie]])<10,"0","") & MONTH(LstMachines[[#This Row],[DatePaie]])&"-"&YEAR(LstMachines[[#This Row],[DatePaie]]) -> 01-2018 | AB28: =LstMachines[[#This Row],[DateLivr]]+1 -> 43055 | AC28: =IF(MONTH(LstMachines[[#This Row],[Distrib]])<10,"0","") & MONTH(LstMachines[[#This Row],[Distrib]]) & "-" & YEAR(LstMachines[[#This Row],[Distrib]]) -> 11-2017 | AD28: =LstMachines[[#This Row],[DateLivr]]+Délai_Vente -> 43174 | AE28: =IF(MONTH(LstMachines[[#This Row],[VteESM]])<10,"0","") & MONTH(LstMachines[[#This Row],[VteESM]]) & "-" & YEAR(LstMachines[[#This Row],[VteESM]]) -> 03-2018 | AF28: =LstMachines[[#This Row],[DateLivr]]+Rglt_à_ESMTP -> 43114 | AG28: =IF(MONTH(LstMachines[[#This Row],[RgltDistrib]])<10,"0","") & MONTH(LstMachines[[#This Row],[RgltDistrib]]) & "-" & YEAR(LstMachines[[#This Row],[RgltDistrib]]) -> 01-2018 | AH28: =LstMachines[[#This Row],[VteESM]]+Rglt_à_ESMTP -> 43234 | AI28: =IF(MONTH(LstMachines[[#This Row],[RgltVteESM]])<10,"0","") & MONTH(LstMachines[[#This Row],[RgltVteESM]]) & "-" & YEAR(LstMachines[[#This Row],[RgltVteESM]]) -> 05-2018 | AJ28: =MONTH(LstMachines[[#This Row],[DatePaie]]) -> 1 | AK28: =FIXED(YEAR(LstMachines[[#This Row],[DatePaie]]),0,TRUE) -> 2018
B29: Pelle/Chenilles | C29: ZX85 | D29: 85 | E29: ZX85USB-5A-Mono | F29: BTPS | G29: ORTHEZ | H29: 1 | I29: =IF(LstMachines[[#This Row],[Delivery]]<Début_HCME, 0, IFERROR( LstMachines[[#This Row],[Nbre]] * INDEX(TabModelSpecs[],MATCH(LstMachines[[#This Row],[Model-Spec]],TabModelSpecs[ModelSpec],0),MATCH("2018",TabModelSpecs[#Headers],0)), LstMachines[[#This Row],[Nbre]]*ROUND(AVERAGEIF(TabModelSpecs[Machine],LstMachines[[#This Row],[Model]],TabModelSpecs[Price]),0) ) ) -> 0 | J29: 43054 | K29: 3-Commande | L29: 2017-11 BTPS | O29: =MONTH(LstMachines[[#This Row],[Delivery]]) -> 11 | P29: =FIXED(YEAR(LstMachines[[#This Row],[Delivery]]),0,TRUE) -> 2017 | X29: =LstMachines[[#This Row],[Delivery]] -> 43054 | Y29: =IF(MONTH(LstMachines[[#This Row],[DateLivr]])<10,"0","") & MONTH(LstMachines[[#This Row],[DateLivr]]) &"-"&YEAR(LstMachines[[#This Row],[DateLivr]]) -> 11-2017 | Z29: =LstMachines[[#This Row],[Delivery]]+Rglt_à_HCME -> 43114 | AA29: =IF(MONTH(LstMachines[[#This Row],[DatePaie]])<10,"0","") & MONTH(LstMachines[[#This Row],[DatePaie]])&"-"&YEAR(LstMachines[[#This Row],[DatePaie]]) -> 01-2018 | AB29: =LstMachines[[#This Row],[DateLivr]]+1 -> 43055 | AC29: =IF(MONTH(LstMachines[[#This Row],[Distrib]])<10,"0","") & MONTH(LstMachines[[#This Row],[Distrib]]) & "-" & YEAR(LstMachines[[#This Row],[Distrib]]) -> 11-2017 | AD29: =LstMachines[[#This Row],[DateLivr]]+Délai_Vente -> 43174 | AE29: =IF(MONTH(LstMachines[[#This Row],[VteESM]])<10,"0","") & MONTH(LstMachines[[#This Row],[VteESM]]) & "-" & YEAR(LstMachines[[#This Row],[VteESM]]) -> 03-2018 | AF29: =LstMachines[[#This Row],[DateLivr]]+Rglt_à_ESMTP -> 43114 | AG29: =IF(MONTH(LstMachines[[#This Row],[RgltDistrib]])<10,"0","") & MONTH(LstMachines[[#This Row],[RgltDistrib]]) & "-" & YEAR(LstMachines[[#This Row],[RgltDistrib]]) -> 01-2018 | AH29: =LstMachines[[#This Row],[VteESM]]+Rglt_à_ESMTP -> 43234 | AI29: =IF(MONTH(LstMachines[[#This Row],[RgltVteESM]])<10,"0","") & MONTH(LstMachines[[#This Row],[RgltVteESM]]) & "-" & YEAR(LstMachines[[#This Row],[RgltVteESM]]) -> 05-2018 | AJ29: =MONTH(LstMachines[[#This Row],[DatePaie]]) -> 1 | AK29: =FIXED(YEAR(LstMachines[[#This Row],[DatePaie]]),0,TRUE) -> 2018
